{
  "comments": [
    {
      "key": {
        "uuid": "0697a45e_4b20a807",
        "filename": "shell/release-job.sh",
        "patchSetId": 1
      },
      "lineNbr": 55,
      "author": {
        "id": 12
      },
      "writtenOn": "2020-01-29T19:42:31Z",
      "side": 1,
      "message": "I think this is caught already,\n\n$ niet \".distribution_type\" test-release.yaml\nElement not found: distribution_type\necho $?\n1",
      "range": {
        "startLine": 55,
        "startChar": 12,
        "endLine": 55,
        "endChar": 76
      },
      "revId": "1591cbc2cf8a6cd9591cf95ef7460ff1d17feffd",
      "serverId": "f2a2391d-0403-4fa5-b183-4056999a8a09",
      "unresolved": true
    },
    {
      "key": {
        "uuid": "948a0976_97f5c61d",
        "filename": "shell/release-job.sh",
        "patchSetId": 1
      },
      "lineNbr": 55,
      "author": {
        "id": 114
      },
      "writtenOn": "2020-01-29T19:47:36Z",
      "side": 1,
      "message": "Yes niet defends against this case and sets a non-zero exit code, but I don\u0027t know where stderr goes in a pipeline like this, certainly nothing appears in the Jenkins console log.  Please see log of failed job that confounded me for quite a while:  https://jenkins.acumos.org/job/python-model-runner-release-verify/2/console",
      "parentUuid": "0697a45e_4b20a807",
      "range": {
        "startLine": 55,
        "startChar": 12,
        "endLine": 55,
        "endChar": 76
      },
      "revId": "1591cbc2cf8a6cd9591cf95ef7460ff1d17feffd",
      "serverId": "f2a2391d-0403-4fa5-b183-4056999a8a09",
      "unresolved": true
    },
    {
      "key": {
        "uuid": "5b4a7aeb_7f553e71",
        "filename": "shell/release-job.sh",
        "patchSetId": 1
      },
      "lineNbr": 55,
      "author": {
        "id": 12
      },
      "writtenOn": "2020-01-29T20:31:57Z",
      "side": 1,
      "message": "I don\u0027t think this will work since the pipe fail exits the script as soon as\nniet \".distribution_type\" \"$release_file\" returns 1\n\nthis could be caught with the schema/release-pypi-schema.yaml\nwhich seems to be missing required distribution type",
      "parentUuid": "948a0976_97f5c61d",
      "range": {
        "startLine": 55,
        "startChar": 12,
        "endLine": 55,
        "endChar": 76
      },
      "revId": "1591cbc2cf8a6cd9591cf95ef7460ff1d17feffd",
      "serverId": "f2a2391d-0403-4fa5-b183-4056999a8a09",
      "unresolved": true
    }
  ]
}